Workbook

Sheet Overview
A1: FC온라인 스쿼드 관리 Overview

Sheet FC온라인_Cases
A1: FC온라인 테스트 케이스
A2: 스크린샷의 구단 관리 > 스쿼드 관리 화면을 기준으로 작성했습니다. 실제 빌드 접근 시 세부 정책과 버전에 맞춰 보완 가능합니다.
A3: Project_Key | B3: Folder_L1 | C3: Folder_L2 | D3: Component | E3: Test_Key_Local | F3: Name | G3: Objective_or_Description | H3: Precondition | I3: Priority | J3: Labels_Tags | K3: Comment | L3: Step_No | M3: Test_Step | N3: Test_Data | O3: Expected_Result | P3: Actual_Result | Q3: note
A4: FCO | B4: 구단 관리 | C4: 스쿼드 관리 | D4: 화면 진입 | E4: FCO-SQD-001 | F4: 스쿼드 관리 화면 진입 Smoke 확인 | G4: 구단 관리 메뉴를 통해 스쿼드 관리 화면에 진입하고 핵심 영역이 표시되는지 확인한다. | H4: 메인 로비 진입 가능 / 스쿼드 관리 메뉴 접근 가능 | I4: Medium | J4: Smoke,Navigation,Layout | K4: 기본 Layout 확인을 Smoke 범위에 통합 | L4: 1 | M4: 메인 로비에서 구단 관리 메뉴를 선택한다. | N4: Menu_ID: CLUB_MANAGEMENT | O4: 구단 관리 하위 메뉴가 표시되며, 스쿼드 관리 메뉴가 선택 가능한 상태로 표시된다. | P4: PASS
L5: 2 | M5: 스쿼드 관리 메뉴를 선택한다. | N5: Menu_ID: SQUAD_MANAGEMENT | O5: 스쿼드 관리 화면으로 이동하고, 화면 제목 또는 Breadcrumb에 `스쿼드 관리`가 표시된다. | P5: PASS
L6: 3 | M6: 화면 로딩 완료 상태를 확인한다. | N6: Timeout: 5초 | O6: 5초 이내에 로딩 인디케이터가 사라진다. | P6: PASS
L7: 4 | M7: 핵심 화면 영역을 확인한다. | N7: 스쿼드 관리 화면 | O7: 선수 배치 영역, 선수 리스트 영역, 총 급여 영역, 저장 버튼이 표시된다. | P7: PASS
L8: 5 | M8: 화면 진입 실패 여부를 확인한다. | N8: 진입 결과 | O8: 오류 팝업, 빈 화면, 무한 로딩, 클라이언트 종료가 발생하지 않는다. | P8: PASS
L9: 6 | M9: 기준 해상도에서 화면 깨짐 여부를 확인한다. | N9: 기준 해상도 | O9: 주요 UI 요소가 겹치거나 잘리지 않고, 깨진 이미지 또는 비정상 텍스트가 표시되지 않는다. | P9: PASS
D10: 요약 정보 | E10: FCO-SQD-002 | F10: 스쿼드 요약 정보 표시 정합성 확인 | G10: 선수 수, 총 급여, 구단 가치가 서로 다른 기준으로 표시되며 혼동되지 않는지 확인한다. | H10: 스쿼드 A / 선발 11명, 교체 5명 / 등록 선수 수 기대값 16명 / 총 급여 302/310 / 구단 가치 24,000,000,000 BP | I10: High | J10: DataIntegrity,Summary | K10: 선수 수와 총 급여 표기 혼동 방지 | L10: 1 | M10: 스쿼드 A의 선발 영역을 확인한다. | N10: 선발 11명 / P-S11-001~P-S11-011 | O10: 선발 영역에 배치된 선수 수가 11명으로 확인된다. | P10: PASS
L11: 2 | M11: 스쿼드 A의 교체 영역을 확인한다. | N11: 교체 5명 / P-SUB-001~P-SUB-005 | O11: 교체 영역에 배치된 선수 수가 5명으로 확인된다. | P11: PASS
L12: 3 | M12: 선발 선수와 교체 선수의 합계를 계산한다. | N12: 선발 11명 + 교체 5명 | O12: 검증 기준 등록 선수 수가 16명으로 산출된다. | P12: PASS
L13: 4 | M13: 우측 선수 리스트의 등록 선수 수를 확인한다. | N13: 기대 등록 선수 수: 16명 | O13: 등록 선수 수는 `16명`으로 표시된다. | P13: PASS
L14: 5 | M14: 총 급여 영역을 확인한다. | N14: 총 급여: 302/310 | O14: `302/310`은 총 급여 현재값/제한값으로 표시된다. | P14: PASS
L15: 6 | M15: 선수 수와 총 급여 표기 혼동 여부를 확인한다. | N15: 등록 선수 수 16명 / 총 급여 302/310 | O15: 등록 선수 수와 총 급여가 서로 다른 영역 또는 라벨로 구분되어 표시된다. | P15: PASS
L16: 7 | M16: 구단 가치 영역을 확인한다. | N16: 구단 가치: 24,000,000,000 BP | O16: 구단 가치는 BP 단위와 천 단위 구분 기호를 포함해 표시된다. | P16: PASS
D17: 총 급여 | E17: FCO-SQD-003 | F17: 총 급여 상세 계산 정합성 확인 | G17: 배치된 선수별 급여 합계가 총 급여 현재값과 일치하는지 확인한다. | H17: 스쿼드 A / 선발 11명 / P-SAL-001~P-SAL-011 급여 합계 302 / 교체 후 총 급여 310/310 구성 가능 | I17: High | J17: DataIntegrity,Salary | K17: 급여 합산 오류는 핵심 정책 결함 | L17: 1 | M17: 배치된 선발 선수 목록을 확인한다. | N17: P-SAL-001~P-SAL-011 | O17: 선발 영역에 급여 검증 대상 선수 11명이 표시된다. | P17: PASS
L18: 2 | M18: 각 선수의 급여 값을 확인한다. | N18: P-SAL-001~P-SAL-011 | O18: 각 선수 카드 또는 상세 정보에서 선수별 급여 값을 확인할 수 있다. | P18: PASS
L19: 3 | M19: 선수별 급여 합계를 계산한다. | N19: 선수별 급여 합계: 302 | O19: 선수별 급여 합계가 302로 계산된다. | P19: PASS
L20: 4 | M20: 총 급여 영역의 현재값을 확인한다. | N20: 총 급여 기대값: 302/310 | O20: 총 급여 현재값은 선수별 급여 합계와 동일한 `302`로 표시된다. | P20: PASS
L21: 5 | M21: 급여가 다른 선수로 교체한다. | N21: 변경 전 302/310 → 변경 후 310/310 | O21: 선수 교체 후 총 급여 산정 조건이 변경된다. | P21: PASS
L22: 6 | M22: 교체 후 총 급여 값을 확인한다. | N22: 변경 후 기대 총 급여: 310/310 | O22: 총 급여 영역이 `310/310`으로 갱신된다. | P22: PASS
L23: 7 | M23: 총 급여 제한값 유지 여부를 확인한다. | N23: 제한값: 310 | O23: 제한값은 변경되지 않고 `310`으로 유지된다. | P23: PASS
D24: 선수 배치 | E24: FCO-SQD-004 | F24: 선수 피치 슬롯 배치 및 급여 반영 확인 | G24: 우측 선수 리스트의 선수를 피치 슬롯에 배치했을 때 선수 정보와 총 급여가 반영되는지 확인한다. | H24: CM 슬롯 배치 가능 / P-CM-001 보유 / P-CM-001: 모드리치 23UCL +5, CM, OVR 111, 급여 24 | I24: Medium | J24: Functional,Placement,Salary | K24: 기본 배치 동작과 급여 반영 검증 | L24: 1 | M24: 우측 선수 리스트에서 배치 대상 선수를 확인한다. | N24: P-CM-001 / 모드리치 23UCL +5 / CM / OVR 111 / 급여 24 | O24: 선수 카드에 선수명, 시즌, 강화 단계, 포지션, OVR, 급여가 표시된다. | P24: PASS
L25: 2 | M25: 배치 대상 선수를 선택한다. | N25: Player_ID: P-CM-001 | O25: 선택한 선수 카드가 선택 상태로 표시된다. | P25: PASS
L26: 3 | M26: CM 슬롯의 기존 상태를 확인한다. | N26: CM 슬롯 빈 슬롯 또는 교체 가능 상태 | O26: CM 슬롯이 배치 가능한 상태로 표시된다. | P26: PASS
L27: 4 | M27: 선택한 선수를 CM 슬롯에 배치한다. | N27: P-CM-001 → CM 슬롯 | O27: CM 슬롯에 P-CM-001의 선수명, 시즌, 포지션, OVR이 표시된다. | P27: PASS
L28: 5 | M28: 총 급여 변화를 확인한다. | N28: 급여 +24 | O28: 총 급여 현재값에 해당 선수의 급여 24가 반영된다. | P28: PASS
L29: 6 | M29: 중복 배치 여부를 확인한다. | N29: Player_ID: P-CM-001 | O29: P-CM-001은 CM 슬롯 1곳에만 배치된다. | P29: PASS
D30: 포지션 제한 | E30: FCO-SQD-005 | F30: GK 선수 필드 포지션 배치 제한 확인 | G30: GK 선수를 필드 포지션에 배치하려고 할 때 배치가 차단되는지 확인한다. | H30: P-GK-001 보유 / P-GK-001: 쿠르투아 23UCL +5, GK, OVR 110, 급여 18 / ST 슬롯에 기존 선수 P-ST-001 배치 완료 | I30: High | J30: Negative,Position | K30: 포지션 정책 검증 | L30: 1 | M30: GK 선수를 선택한다. | N30: P-GK-001 / 쿠르투아 23UCL +5 / GK / OVR 110 / 급여 18 | O30: 선택한 선수의 포지션이 GK로 확인된다. | P30: PASS
L31: 2 | M31: ST 슬롯의 기존 배치 상태를 확인한다. | N31: ST 슬롯 기존 선수: P-ST-001 | O31: ST 슬롯에 기존 선수가 표시된다. | P31: PASS
L32: 3 | M32: GK 선수를 ST 슬롯에 배치 시도한다. | N32: P-GK-001 → ST 슬롯 | O32: GK 선수는 ST 슬롯에 배치되지 않는다. | P32: Pass
L33: 4 | M33: 안내 메시지를 확인한다. | N33: 기대 메시지: 해당 포지션에 배치할 수 없는 선수입니다. | O33: 안내 메시지가 1회 표시된다. | P33: PASS
L34: 5 | M34: ST 슬롯 상태를 다시 확인한다. | N34: ST 슬롯 기존 선수: P-ST-001 | O34: 기존 ST 슬롯 선수는 변경되지 않는다. | P34: PASS
L35: 6 | M35: GK 선수의 기존 위치를 확인한다. | N35: Player_ID: P-GK-001 | O35: GK 선수는 기존 위치 또는 선수 리스트에 유지된다. | P35: PASS
D36: 자동 편성 | E36: FCO-SQD-006 | F36: 자동 편성 시 포지션·급여·OVR 우선순위 적용 확인 | G36: 자동 편성 실행 시 선수 배치 기준이 일관되게 적용되고 총 급여 제한을 초과하지 않는지 확인한다. | H36: 보유 선수 18명 이상 / GK, DF, MF, FW 후보 존재 / 총 급여 제한값 310 / ST 후보 P-ST-001(OVR 115, 급여 28), P-ST-002(OVR 112, 급여 25) 보유 | I36: High | J36: AutoSquad,Algorithm,Salary | K36: 동일 OVR/동일 포지션 세부 조건 통합 | L36: 1 | M36: 자동 편성 대상 선수 보유 상태를 확인한다. | N36: 보유 선수 18명 이상 | O36: 자동 편성에 필요한 선수 후보가 표시된다. | P36: PASS
L37: 2 | M37: 포지션별 후보 선수를 확인한다. | N37: GK, DF, MF, FW 후보 존재 | O37: GK, DF, MF, FW 포지션 후보가 자동 편성에 필요한 수량 이상 존재한다. | P37: PASS
L38: 3 | M38: 자동 편성 기준 검증용 ST 후보 정보를 확인한다. | N38: P-ST-001 / OVR 115 / 급여 28, P-ST-002 / OVR 112 / 급여 25 | O38: 두 선수 모두 ST 포지션 후보로 표시된다. | P38: PASS
L39: 4 | M39: 동일 포지션 후보의 강화 단계와 가치 정보를 확인한다. | N39: P-ST-001 +5 / P-ST-002 +5 / 가치 정보 표시 | O39: 자동 편성 우선순위 판단에 필요한 OVR, 강화 단계, 가치가 확인 가능하다. | P39: PASS
L40: 5 | M40: 총 급여 제한값을 확인한다. | N40: 총 급여 제한값: 310 | O40: 총 급여 제한값이 `310`으로 표시된다. | P40: PASS
...

Sheet  Dashboard
A1: FC온라인 스쿼드 관리 Dashboard
A5: FC온라인_Cases 시트 기준 테스크 결과 및 리스크 분포 집계
A8: PASS | B8: =COUNTIF(FC온라인_Cases!P4:P220,"PASS") -> 213 | I8: Block 사유 | J8: Count | K8: Detail
A9: FAIL | B9: =COUNTIF(FC온라인_Cases!P4:P220,"FAIL") -> 0 | I9: 테스트 데이터 미보유 | J9: 4 | K9: 요구 강화 수치의 선수 카드 미보유로 실행 보류
A10: BLOCK | B10: =COUNTIF(FC온라인_Cases!P4:P220,"BLOCK") -> 4
A11: PASS Rate | B11: =COUNTIF(FC온라인_Cases!P4:P220,"PASS")/COUNTA(FC온라인_Cases!P4:P220) -> 0.98156682
A12: BLOCK Rate | B12: =COUNTIF(FC온라인_Cases!P4:P220,"BLOCK")/COUNTA(FC온라인_Cases!P4:P220) -> 0.01843318
A13: Total Step | B13: =COUNTA(FC온라인_Cases!P4:P220) -> 217
A14: Total TC | B14: =COUNTA(FC온라인_Cases!E4:E220) -> 37
A16: Priority별 TC분포
J18: 주요 리스크
A19: Priority | B19: TC Count | C19: 비율 | J19: 급여 제한 초과 상태 저장
A20: Critical | B20: =COUNTIF(FC온라인_Cases!I4:I220,"Critical") -> 7 | C20: =IFERROR(B20/SUM($B$20:$B$23),0) -> 0.18918919 | J20: 포지션 제한 무시
A21: High | B21: =COUNTIF(FC온라인_Cases!I4:I220,"High") -> 23 | C21: =IFERROR(B21/SUM($B$20:$B$23),0) -> 0.62162162 | J21: 선발 인원 부족 상태 저장
A22: Medium | B22: =COUNTIF(FC온라인_Cases!I4:I220,"Medium") -> 7 | C22: =IFERROR(B22/SUM($B$20:$B$23),0) -> 0.18918919 | J22: 저장 후 스쿼드 데이터 유실
A23: Low | B23: =COUNTIF(FC온라인_Cases!I4:I220,"Low") -> 0 | C23: =IFERROR(B23/SUM($B$20:$B$23),0) -> 0 | J23: 스쿼드 간 데이터 오염
A24: Total | B24: =COUNTIF(FC온라인_Cases!I4:I220,"Critical")+COUNTIF(FC온라인_Cases!I4:I220,"High")+COUNTIF(FC온라인_Cases!I4:I220,"Medium")+COUNTIF(FC온라인_Cases!I4:I220,"Low") -> 37 | C24: 1 | J24: 팀컬러 적용 상태 불일ㄹ치
A26: Component별 TC분포
A29: No | B29: Component | C29: Step Count | D29: Rate | J29: 테스트 진행환경
A30: 1 | B30: 화면 진입 | C30: {=SUMPRODUCT((LOOKUP(ROW(FC온라인_Cases!$D$4:$D$220),ROW(FC온라인_Cases!$D$4:$D$220)/(FC온라인_Cases!$D$4:$D$220<>""),FC온라인_Cases!$D$4:$D$220)=B30)*(FC온라인_Cases!$L$4:$L$220<>""))} -> 6 | D30: =IFERROR(C30/$C$47,0) -> 0.02764977 | J30: PC spec | K30: 운영체제 | L30: window 11
A31: 2 | B31: 요약 정보 | C31: {=SUMPRODUCT((LOOKUP(ROW(FC온라인_Cases!$D$4:$D$220),ROW(FC온라인_Cases!$D$4:$D$220)/(FC온라인_Cases!$D$4:$D$220<>""),FC온라인_Cases!$D$4:$D$220)=B31)*(FC온라인_Cases!$L$4:$L$220<>""))} -> 7 | D31: =IFERROR(C31/$C$47,0) -> 0.032258065 | K31: DirectX 버전 | L31: DirextX 12
A32: 3 | B32: 총 급여 | C32: {=SUMPRODUCT((LOOKUP(ROW(FC온라인_Cases!$D$4:$D$220),ROW(FC온라인_Cases!$D$4:$D$220)/(FC온라인_Cases!$D$4:$D$220<>""),FC온라인_Cases!$D$4:$D$220)=B32)*(FC온라인_Cases!$L$4:$L$220<>""))} -> 7 | D32: =IFERROR(C32/$C$47,0) -> 0.032258065 | K32: GPU | L32: NVIDIA RTX 4060 TI
A33: 4 | B33: 선수 배치 | C33: {=SUMPRODUCT((LOOKUP(ROW(FC온라인_Cases!$D$4:$D$220),ROW(FC온라인_Cases!$D$4:$D$220)/(FC온라인_Cases!$D$4:$D$220<>""),FC온라인_Cases!$D$4:$D$220)=B33)*(FC온라인_Cases!$L$4:$L$220<>""))} -> 6 | D33: =IFERROR(C33/$C$47,0) -> 0.02764977 | K33: CPU | L33: AMD RYZEN 5 7500F
A34: 5 | B34: 포지션 제한 | C34: {=SUMPRODUCT((LOOKUP(ROW(FC온라인_Cases!$D$4:$D$220),ROW(FC온라인_Cases!$D$4:$D$220)/(FC온라인_Cases!$D$4:$D$220<>""),FC온라인_Cases!$D$4:$D$220)=B34)*(FC온라인_Cases!$L$4:$L$220<>""))} -> 13 | D34: =IFERROR(C34/$C$47,0) -> 0.059907834 | K34: RAM | L34: 32GB
A35: 6 | B35: 자동 편성 | C35: {=SUMPRODUCT((LOOKUP(ROW(FC온라인_Cases!$D$4:$D$220),ROW(FC온라인_Cases!$D$4:$D$220)/(FC온라인_Cases!$D$4:$D$220<>""),FC온라인_Cases!$D$4:$D$220)=B35)*(FC온라인_Cases!$L$4:$L$220<>""))} -> 24 | D35: =IFERROR(C35/$C$47,0) -> 0.11059908
A36: 7 | B36: 저장 | C36: {=SUMPRODUCT((LOOKUP(ROW(FC온라인_Cases!$D$4:$D$220),ROW(FC온라인_Cases!$D$4:$D$220)/(FC온라인_Cases!$D$4:$D$220<>""),FC온라인_Cases!$D$4:$D$220)=B36)*(FC온라인_Cases!$L$4:$L$220<>""))} -> 8 | D36: =IFERROR(C36/$C$47,0) -> 0.036866359 | J36: Game Version | K36: FC온라인 라이브서비스 기준
A37: 8 | B37: 팀컬러 | C37: {=SUMPRODUCT((LOOKUP(ROW(FC온라인_Cases!$D$4:$D$220),ROW(FC온라인_Cases!$D$4:$D$220)/(FC온라인_Cases!$D$4:$D$220<>""),FC온라인_Cases!$D$4:$D$220)=B37)*(FC온라인_Cases!$L$4:$L$220<>""))} -> 13 | D37: =IFERROR(C37/$C$47,0) -> 0.059907834 | J37: Test Data | K37: 2026년 7월6일
A38: 9 | B38: 급여 제한 | C38: {=SUMPRODUCT((LOOKUP(ROW(FC온라인_Cases!$D$4:$D$220),ROW(FC온라인_Cases!$D$4:$D$220)/(FC온라인_Cases!$D$4:$D$220<>""),FC온라인_Cases!$D$4:$D$220)=B38)*(FC온라인_Cases!$L$4:$L$220<>""))} -> 20 | D38: =IFERROR(C38/$C$47,0) -> 0.092165899
A39: 10 | B39: 선수 수 | C39: {=SUMPRODUCT((LOOKUP(ROW(FC온라인_Cases!$D$4:$D$220),ROW(FC온라인_Cases!$D$4:$D$220)/(FC온라인_Cases!$D$4:$D$220<>""),FC온라인_Cases!$D$4:$D$220)=B39)*(FC온라인_Cases!$L$4:$L$220<>""))} -> 12 | D39: =IFERROR(C39/$C$47,0) -> 0.055299539
A40: 11 | B40: 포메이션 | C40: {=SUMPRODUCT((LOOKUP(ROW(FC온라인_Cases!$D$4:$D$220),ROW(FC온라인_Cases!$D$4:$D$220)/(FC온라인_Cases!$D$4:$D$220<>""),FC온라인_Cases!$D$4:$D$220)=B40)*(FC온라인_Cases!$L$4:$L$220<>""))} -> 6 | D40: =IFERROR(C40/$C$47,0) -> 0.02764977
A41: 12 | B41: 선수 교체 | C41: {=SUMPRODUCT((LOOKUP(ROW(FC온라인_Cases!$D$4:$D$220),ROW(FC온라인_Cases!$D$4:$D$220)/(FC온라인_Cases!$D$4:$D$220<>""),FC온라인_Cases!$D$4:$D$220)=B41)*(FC온라인_Cases!$L$4:$L$220<>""))} -> 19 | D41: =IFERROR(C41/$C$47,0) -> 0.087557604
A42: 13 | B42: 가치 표시 | C42: {=SUMPRODUCT((LOOKUP(ROW(FC온라인_Cases!$D$4:$D$220),ROW(FC온라인_Cases!$D$4:$D$220)/(FC온라인_Cases!$D$4:$D$220<>""),FC온라인_Cases!$D$4:$D$220)=B42)*(FC온라인_Cases!$L$4:$L$220<>""))} -> 15 | D42: =IFERROR(C42/$C$47,0) -> 0.069124424
A43: 14 | B43: 데이터 동기화 | C43: {=SUMPRODUCT((LOOKUP(ROW(FC온라인_Cases!$D$4:$D$220),ROW(FC온라인_Cases!$D$4:$D$220)/(FC온라인_Cases!$D$4:$D$220<>""),FC온라인_Cases!$D$4:$D$220)=B43)*(FC온라인_Cases!$L$4:$L$220<>""))} -> 23 | D43: =IFERROR(C43/$C$47,0) -> 0.10599078
A44: 15 | B44: UI 예외 | C44: {=SUMPRODUCT((LOOKUP(ROW(FC온라인_Cases!$D$4:$D$220),ROW(FC온라인_Cases!$D$4:$D$220)/(FC온라인_Cases!$D$4:$D$220<>""),FC온라인_Cases!$D$4:$D$220)=B44)*(FC온라인_Cases!$L$4:$L$220<>""))} -> 6 | D44: =IFERROR(C44/$C$47,0) -> 0.02764977
A45: 16 | B45: 선수 상세 진입 | C45: {=SUMPRODUCT((LOOKUP(ROW(FC온라인_Cases!$D$4:$D$220),ROW(FC온라인_Cases!$D$4:$D$220)/(FC온라인_Cases!$D$4:$D$220<>""),FC온라인_Cases!$D$4:$D$220)=B45)*(FC온라인_Cases!$L$4:$L$220<>""))} -> 8 | D45: =IFERROR(C45/$C$47,0) -> 0.036866359
A46: 17 | B46: 획득 특성 | C46: {=SUMPRODUCT((LOOKUP(ROW(FC온라인_Cases!$D$4:$D$220),ROW(FC온라인_Cases!$D$4:$D$220)/(FC온라인_Cases!$D$4:$D$220<>""),FC온라인_Cases!$D$4:$D$220)=B46)*(FC온라인_Cases!$L$4:$L$220<>""))} -> 24 | D46: =IFERROR(C46/$C$47,0) -> 0.11059908
A47: Total | C47: 217 | D47: 1
